Workbook

Sheet Relatorio_Validar
A1: numero_ticket | B1: Data_entrada | C1: Assunto_ticket | D1: Título_ticket | E1: Usuario_criador_ticket | F1: Status_ticket | G1: Grupo_responsavel_ticket | H1: Responsavel_ticket | I1: Tags_ticket | J1: Total_interações
A2: 184750 | B2: 45474.209 | D2: [Granatum] Aviso de Agendamentos Pendentes | E2: Granatum | F2: Cancelado | G2: Suporte | H2: Lucas Muniz | I2: - | J2: 2
A3: 184751 | B3: 45474.375 | D3: ✨ Retently Monthly Digest for Octadesk (June 2024) | E3: Retently Digests | F3: Cancelado | G3: Suporte | H3: Lucas Muniz | I3: - | J3: 2
A4: 184752 | B4: 45474.385 | D4: Olá José Ribamar Cosme farias, aqui está nossa conversa! | E4: José Ribamar Cosme farias | F4: Cancelado | G4: Suporte | H4: Lucas Muniz | I4: - | J4: 2
A5: 184753 | B5: 45474.421 | D5: Teste help em beta | E5: William Lima | F5: Cancelado | G5: Suporte | I5: - | J5: 2
A6: 184754 | B6: 45474.442 | D6: Your Datadog Plan Was Converted to Free | E6: Datadog | F6: Cancelado | G6: Suporte | H6: Lucas Muniz | I6: - | J6: 2
A7: 184755 | B7: 45474.447 | D7: [Incidente] não localiza ticket ao pesquisar - cibracoimoveis #184554 #157512 | E7: atendimento | F7: Cancelado | G7: Suporte | H7: Lucas Muniz | I7: - | J7: 2
A8: 184756 | B8: 45474.458 | C8: 3080 Tickets abertos | D8: Menção não funciona em tickets - o180711-06d | E8: Natalia Schuch | F8: Resolvido | G8: N2 | I8: chat, 184728, ticket-corrigido | J8: 6
A9: 184757 | B9: 45474.46 | D9: Announcing Warehouse Connectors 2.0 | E9: Mixpanel | F9: Cancelado | G9: Suporte | H9: Lucas Muniz | I9: - | J9: 2
A10: 184758 | B10: 45474.468 | C10: 3058 Backup | D10: Backup da conta | E10: rennie | F10: Resolvido | G10: N2 | H10: Gabrielle | I10: chat, problema-envio-email | J10: 9
A11: 184759 | B11: 45474.469 | D11: Será VOCÊ o(a) melhor jogador(a) do Brasil? | E11: Poker de Botequim | F11: Cancelado | G11: Suporte | H11: Lucas Muniz | I11: - | J11: 4
A12: 184760 | B12: 45474.469 | C12: 3080 Tickets abertos | D12: Menção nos tickets não está funcionando | E12: Bruno | F12: Resolvido | G12: N2 | I12: chat, ticket-corrigido | J12: 8
A13: 184761 | B13: 45474.475 | C13: 3080 Tickets abertos | D13: Menção nos tickets não está funcionando | E13: Andre Leite Souza | F13: Resolvido | G13: N2 | I13: chat, 184728, ticket-corrigido | J13: 10
A14: 184762 | B14: 45474.488 | C14: 3038 Exportar | D14: Download de relatório de tickets não aparece nas notificações - o179024-820 | E14: Phylipe | F14: Resolvido | G14: N2 | H14: Gabrielle | I14: chat | J14: 8
A15: 184763 | B15: 45474.509 | C15: 3012 Anotação interna | D15: Erro ao realizar menção a agente dentro de ticket | E15: Érica Oliveira | F15: Resolvido | G15: N2 | H15: Gabrielle A. | I15: chat, 184728, ticket-corrigido | J15: 11
A16: 184764 | B16: 45474.512 | D16: Smartband Samsung Galaxy Fit 3 a partir de R$ 277,92*!🔥 | E16: Fujioka Distribuidor | F16: Cancelado | G16: Suporte | H16: Lucas Muniz | I16: - | J16: 2
A17: 184765 | B17: 45474.515 | C17: 3012 Anotação interna | D17: Erro ao realizar menção a agente dentro de ticket | E17: Renato Herrerias Bueno | F17: Resolvido | G17: N2 | I17: chat, Automacao-Encerra-72hrs | J17: 8
A18: 184766 | B18: 45474.516 | C18: Análise da aplicação | Pods em CrashLoopBack | D18: Direcionar alertas de filas para o canal do helpdesk | E18: William Lima | F18: Resolvido | G18: PROD - Infra | I18: monitoramento | J18: 2
A19: 184767 | B19: 45474.523 | C19: 3137 Adicionar Número Web | D19: Retorno conversa ID: 240701775243 | E19: Saulo S. | F19: Resolvido | G19: Suporte | H19: Saulo S. | I19: - | J19: 2
A20: 184768 | B20: 45474.524 | C20: Análise da aplicação | Pods em CrashLoopBack | D20: Direcionar alertas de serviços para o canal do helpdesk | E20: William Lima | F20: Resolvido | G20: PROD - Infra | I20: monitoramento, problema-envio-email | J20: 3
A21: 184769 | B21: 45474.525 | C21: 3058 Backup | D21: Backup - Total de Conversas. | E21: Daniel | F21: Resolvido | G21: N2 | H21: Gabrielle A. | I21: chat, Automacao-Encerra-72hrs | J21: 9
A22: 184770 | B22: 45474.535 | D22: 30% OFF NA VOLTA ÀS AULAS LEGALE! 📚 | E22: Legale Educacional | F22: Cancelado | G22: Suporte | H22: Lucas Muniz | I22: - | J22: 2
A23: 184771 | B23: 45474.541 | D23: Your Daily Digest from Datadog | E23: Datadog | F23: Cancelado | G23: Suporte | H23: Lucas Muniz | I23: - | J23: 2
A24: 184772 | B24: 45474.584 | D24: Aumente a Conscientização com Brindes Personalizados! | E24: Juana | F24: Cancelado | G24: Suporte | H24: Lucas Muniz | I24: - | J24: 2
A25: 184773 | B25: 45474.612 | D25: Convite para se juntar ao Octadesk | E25: octadesk | efetivação de plano | F25: Cancelado | G25: Suporte | H25: Lucas Muniz | I25: - | J25: 2
A26: 184774 | B26: 45474.619 | D26: TICKET CLIENTE - EXEMPLO | E26: Patricia Oliveira | F26: Cancelado | G26: Suporte | H26: Lucas Muniz | I26: - | J26: 3
A27: 184775 | B27: 45474.623 | D27: Alguns clientes não tem os dados alterados no momento da conversa - o179673-362 #184122 | E27: Fernando Pesaro | F27: Resolvido | G27: Suporte | H27: Lucas Muniz | I27: - | J27: 2
A28: 184776 | B28: 45474.635 | D28: Máscara para CPAP e BiPAP 🎁 | E28: Geferson | F28: Cancelado | G28: Suporte | H28: Lucas Muniz | I28: - | J28: 2
A29: 184777 | B29: 45474.639 | C29: 3012 Anotação interna | D29: Erro ao realizar menção a agente dentro de ticket | E29: joao | F29: Resolvido | G29: N2 | I29: chat, 184728, ticket-corrigido | J29: 7
A30: 184778 | B30: 45474.639 | D30: LAB8 EMPRESA DE MARKETING E PUBLICIDADE - NFS-e Nº 816 | E30: LOBBY TECH | F30: Cancelado | G30: Suporte | H30: Lucas Muniz | I30: - | J30: 2
A31: 184779 | B31: 45474.658 | D31: Recuperação de Conta | E31: Beatriz Ahmed | F31: Resolvido | G31: Suporte | H31: Lucas Muniz | I31: automacao-24horas, Automacao-Encerra-72hrs | J31: 8
A32: 184780 | B32: 45474.669 | C32: 3080 Tickets abertos | D32: Chat com Pedro Lopes iniciada às 01/07/2024 15:27 | E32: Pedro Lopes | F32: Resolvido | G32: N2 | I32: chat, ticket-corrigido | J32: 6
A33: 184781 | B33: 45474.677 | C33: 3080 Tickets abertos | D33: Menção nos tickets não está funcionando | E33: joao.rodrigues | F33: Resolvido | G33: N2 | I33: chat, 184728, ticket-corrigido | J33: 9
A34: 184782 | B34: 45474.689 | C34: 3080 Tickets abertos | D34: Menção nos tickets não está funcionando | E34: Octo O. Amarelo | F34: Resolvido | G34: Suporte | I34: chat, 184728, ticket-corrigido, problema-envio-email | J34: 9
A35: 184783 | B35: 45474.697 | C35: 3011 Notificação | D35: Lembrete não gerou notificação na barra de notificações | E35: Daniel | F35: Resolvido | G35: N2 | H35: Juan C. | I35: chat, 184971, ticket-corrigido | J35: 14
A36: 184784 | B36: 45474.7 | D36: Resposta automática: Erro Octadesk - Cliente não encontrada #184007 | E36: Andressa Favacho | F36: Cancelado | G36: Suporte | I36: - | J36: 2
A37: 184785 | B37: 45474.703 | D37: Migração Número WhatsApp | E37: Patricia | F37: Cancelado | G37: Suporte | I37: - | J37: 2
A38: 184786 | B38: 45474.705 | D38: Erro de Mensagens | E38: Patricia | F38: Resolvido | G38: Suporte | H38: Lucas Muniz | I38: - | J38: 3
A39: 184787 | B39: 45474.708 | C39: 3028 Restringir | D39: Pré-visualização de conversas restritas para agentes que não deveriam ter acesso | E39: Jessica Wettermann | F39: Resolvido | G39: N2 | H39: Juan C. | I39: chat, 185628, ticket-corrigido | J39: 35
A40: 184788 | B40: 45474.713 | C40: 3058 Backup | D40: PROD - Infra - Backup da collection planoeplano_ticketarchived e informações sobre tamanho de uso de armazenamento - planoeplano | E40: Juan C. | F40: Resolvido | G40: PROD - Infra | I40: 184421, problema-envio-email | J40: 4
...

Sheet Base
A1: ticket | B1: data_entrada
A2: 184750 | B2: 45474.209
A3: 184751 | B3: 45474.375
A4: 184752 | B4: 45474.385
A5: 184753 | B5: 45474.421
A6: 184754 | B6: 45474.442
A7: 184755 | B7: 45474.447
A8: 184756 | B8: 45474.458
A9: 184757 | B9: 45474.46
A10: 184758 | B10: 45474.468
A11: 184759 | B11: 45474.469
A12: 184760 | B12: 45474.469
A13: 184761 | B13: 45474.475
... A8262: 193280 | B8262: 45781.834

Sheet Relatorio
B1: ticket | C1: Validação | D1: Data_entrada | E1: Data_resolução | F1: Data_resolucao | G1: Titulo_ticket | H1: Usuario_criador_ticket | I1: Status | J1: Grupo_responsavel | K1: Responsavel_ticket | L1: Tags_ticket | M1: Total_de_interacoes
B2: 193140 | C2: =IFERROR(VLOOKUP(Relatorio_[[#This Row],[ticket]],Base!A:A,1,0),"-") -> 193140 | D2: 45777.335 | E2: 45777.466 | F2: =IF(Relatorio_[[#This Row],[Data_resolução]]=0,"",Relatorio_[[#This Row],[Data_resolução]]) -> 45777.466 | G2: [IMPORTANTE] Conta PJ sem em andamento | H2: Inter Empresas | I2: Cancelado | J2: Financeiro | L2: - | M2: 2 | O2: ="INSERT INTO octadesk.stickets ("&$B$1&","&$D$1&","&$F$1&","&$G$1&","&$H$1&","&$I$1&","&$J$1&","&$K$1&","&$L$1&","&$M$1&") values("&IF(B2="","NULL","'"&B2&"'")&",'"&TEXT(D2,"aaaa-mm-dd hh:mm:ss")&"',"&IF(E2="","NULL","'"&TEXT(E2,"aaaa-mm-dd hh:mm:ss")&"'")&","&IF(G2="","NULL","'"&G2&"'")&","&IF(H2="","NULL","'"&H2&"'")&","&IF(I2="","NULL","'"&I2&"'")&","&IF(J2="","NULL","'"&J2&"'")&","&IF(K2="","NULL","'"&K2&"'")&","&IF(L2="","NULL","'"&L2&"'")&","&IF(M2="","NULL","'"&M2&"'")&");" -> INSERT INTO octadesk.stickets (ticket,Data_entrada,Data_resolucao,Titulo_ticket,Usuario_criador_ticket,Status,Grupo_responsavel,Responsavel_ticket,Tags_ticket,Total_de_interacoes) values('193140','2025-04-30 08:03:03','2025-04-30 11:10:39','[IMPORTANTE] Conta PJ sem em andamento','Inter Empresas','Cancelado','Financeiro',NULL,'-','2');
B3: 193141 | C3: =IFERROR(VLOOKUP(Relatorio_[[#This Row],[ticket]],Base!A:A,1,0),"-") -> 193141 | D3: 45777.378 | E3: 45778.591 | F3: =IF(Relatorio_[[#This Row],[Data_resolução]]=0,"",Relatorio_[[#This Row],[Data_resolução]]) -> 45778.591 | G3: Solicitação de suporte interno | H3: Suporte Octadesk | I3: Resolvido | J3: Suporte | K3: Brenda | L3: suporte-interno | M3: 8 | O3: ="INSERT INTO octadesk.stickets ("&$B$1&","&$D$1&","&$F$1&","&$G$1&","&$H$1&","&$I$1&","&$J$1&","&$K$1&","&$L$1&","&$M$1&") values("&IF(B3="","NULL","'"&B3&"'")&",'"&TEXT(D3,"aaaa-mm-dd hh:mm:ss")&"',"&IF(E3="","NULL","'"&TEXT(E3,"aaaa-mm-dd hh:mm:ss")&"'")&","&IF(G3="","NULL","'"&G3&"'")&","&IF(H3="","NULL","'"&H3&"'")&","&IF(I3="","NULL","'"&I3&"'")&","&IF(J3="","NULL","'"&J3&"'")&","&IF(K3="","NULL","'"&K3&"'")&","&IF(L3="","NULL","'"&L3&"'")&","&IF(M3="","NULL","'"&M3&"'")&");" -> INSERT INTO octadesk.stickets (ticket,Data_entrada,Data_resolucao,Titulo_ticket,Usuario_criador_ticket,Status,Grupo_responsavel,Responsavel_ticket,Tags_ticket,Total_de_interacoes) values('193141','2025-04-30 09:04:14','2025-05-01 14:10:35','Solicitação de suporte interno','Suporte Octadesk','Resolvido','Suporte','Brenda','suporte-interno','8');
B4: 193142 | C4: =IFERROR(VLOOKUP(Relatorio_[[#This Row],[ticket]],Base!A:A,1,0),"-") -> 193142 | D4: 45777.395 | F4: =IF(Relatorio_[[#This Row],[Data_resolução]]=0,"",Relatorio_[[#This Row],[Data_resolução]]) | G4: Troca de titularidade - CONECTA SERVICOS DE TI LTDA | H4: Marcos | I4: Em andamento | J4: Financeiro | L4: - | M4: 2 | O4: ="INSERT INTO octadesk.stickets ("&$B$1&","&$D$1&","&$F$1&","&$G$1&","&$H$1&","&$I$1&","&$J$1&","&$K$1&","&$L$1&","&$M$1&") values("&IF(B4="","NULL","'"&B4&"'")&",'"&TEXT(D4,"aaaa-mm-dd hh:mm:ss")&"',"&IF(E4="","NULL","'"&TEXT(E4,"aaaa-mm-dd hh:mm:ss")&"'")&","&IF(G4="","NULL","'"&G4&"'")&","&IF(H4="","NULL","'"&H4&"'")&","&IF(I4="","NULL","'"&I4&"'")&","&IF(J4="","NULL","'"&J4&"'")&","&IF(K4="","NULL","'"&K4&"'")&","&IF(L4="","NULL","'"&L4&"'")&","&IF(M4="","NULL","'"&M4&"'")&");" -> INSERT INTO octadesk.stickets (ticket,Data_entrada,Data_resolucao,Titulo_ticket,Usuario_criador_ticket,Status,Grupo_responsavel,Responsavel_ticket,Tags_ticket,Total_de_interacoes) values('193142','2025-04-30 09:28:47',NULL,'Troca de titularidade - CONECTA SERVICOS DE TI LTDA','Marcos','Em andamento','Financeiro',NULL,'-','2');
B5: 193143 | C5: =IFERROR(VLOOKUP(Relatorio_[[#This Row],[ticket]],Base!A:A,1,0),"-") -> 193143 | D5: 45777.403 | F5: =IF(Relatorio_[[#This Row],[Data_resolução]]=0,"",Relatorio_[[#This Row],[Data_resolução]]) | G5: Conversas fugiram do fluxo de horário de atendimento | H5: Ailton | I5: Novo | J5: N2 | L5: chat | M5: 6 | O5: ="INSERT INTO octadesk.stickets ("&$B$1&","&$D$1&","&$F$1&","&$G$1&","&$H$1&","&$I$1&","&$J$1&","&$K$1&","&$L$1&","&$M$1&") values("&IF(B5="","NULL","'"&B5&"'")&",'"&TEXT(D5,"aaaa-mm-dd hh:mm:ss")&"',"&IF(E5="","NULL","'"&TEXT(E5,"aaaa-mm-dd hh:mm:ss")&"'")&","&IF(G5="","NULL","'"&G5&"'")&","&IF(H5="","NULL","'"&H5&"'")&","&IF(I5="","NULL","'"&I5&"'")&","&IF(J5="","NULL","'"&J5&"'")&","&IF(K5="","NULL","'"&K5&"'")&","&IF(L5="","NULL","'"&L5&"'")&","&IF(M5="","NULL","'"&M5&"'")&");" -> INSERT INTO octadesk.stickets (ticket,Data_entrada,Data_resolucao,Titulo_ticket,Usuario_criador_ticket,Status,Grupo_responsavel,Responsavel_ticket,Tags_ticket,Total_de_interacoes) values('193143','2025-04-30 09:40:44',NULL,'Conversas fugiram do fluxo de horário de atendimento','Ailton','Novo','N2',NULL,'chat','6');
B6: 193144 | C6: =IFERROR(VLOOKUP(Relatorio_[[#This Row],[ticket]],Base!A:A,1,0),"-") -> 193144 | D6: 45777.413 | F6: =IF(Relatorio_[[#This Row],[Data_resolução]]=0,"",Relatorio_[[#This Row],[Data_resolução]]) | G6: Possibilidade de LOG de exclusão de usuário - runningsolutions | H6: JULIANO MARTINS MENESES | I6: Pendente | J6: N2 | L6: chat, problema-envio-email | M6: 7 | O6: ="INSERT INTO octadesk.stickets ("&$B$1&","&$D$1&","&$F$1&","&$G$1&","&$H$1&","&$I$1&","&$J$1&","&$K$1&","&$L$1&","&$M$1&") values("&IF(B6="","NULL","'"&B6&"'")&",'"&TEXT(D6,"aaaa-mm-dd hh:mm:ss")&"',"&IF(E6="","NULL","'"&TEXT(E6,"aaaa-mm-dd hh:mm:ss")&"'")&","&IF(G6="","NULL","'"&G6&"'")&","&IF(H6="","NULL","'"&H6&"'")&","&IF(I6="","NULL","'"&I6&"'")&","&IF(J6="","NULL","'"&J6&"'")&","&IF(K6="","NULL","'"&K6&"'")&","&IF(L6="","NULL","'"&L6&"'")&","&IF(M6="","NULL","'"&M6&"'")&");" -> INSERT INTO octadesk.stickets (ticket,Data_entrada,Data_resolucao,Titulo_ticket,Usuario_criador_ticket,Status,Grupo_responsavel,Responsavel_ticket,Tags_ticket,Total_de_interacoes) values('193144','2025-04-30 09:54:22',NULL,'Possibilidade de LOG de exclusão de usuário - runningsolutions','JULIANO MARTINS MENESES','Pendente','N2',NULL,'chat, problema-envio-email','7');
B7: 193145 | C7: =IFERROR(VLOOKUP(Relatorio_[[#This Row],[ticket]],Base!A:A,1,0),"-") -> 193145 | D7: 45777.414 | F7: =IF(Relatorio_[[#This Row],[Data_resolução]]=0,"",Relatorio_[[#This Row],[Data_resolução]]) | G7: Solicitação de suporte interno | H7: Suporte Octadesk | I7: Pendente | J7: Suporte | K7: Brenda | L7: suporte-interno, automacao-24horas | M7: 6 | O7: ="INSERT INTO octadesk.stickets ("&$B$1&","&$D$1&","&$F$1&","&$G$1&","&$H$1&","&$I$1&","&$J$1&","&$K$1&","&$L$1&","&$M$1&") values("&IF(B7="","NULL","'"&B7&"'")&",'"&TEXT(D7,"aaaa-mm-dd hh:mm:ss")&"',"&IF(E7="","NULL","'"&TEXT(E7,"aaaa-mm-dd hh:mm:ss")&"'")&","&IF(G7="","NULL","'"&G7&"'")&","&IF(H7="","NULL","'"&H7&"'")&","&IF(I7="","NULL","'"&I7&"'")&","&IF(J7="","NULL","'"&J7&"'")&","&IF(K7="","NULL","'"&K7&"'")&","&IF(L7="","NULL","'"&L7&"'")&","&IF(M7="","NULL","'"&M7&"'")&");" -> INSERT INTO octadesk.stickets (ticket,Data_entrada,Data_resolucao,Titulo_ticket,Usuario_criador_ticket,Status,Grupo_responsavel,Responsavel_ticket,Tags_ticket,Total_de_interacoes) values('193145','2025-04-30 09:56:21',NULL,'Solicitação de suporte interno','Suporte Octadesk','Pendente','Suporte','Brenda','suporte-interno, automacao-24horas','6');
B8: 193146 | C8: =IFERROR(VLOOKUP(Relatorio_[[#This Row],[ticket]],Base!A:A,1,0),"-") -> 193146 | D8: 45777.423 | F8: =IF(Relatorio_[[#This Row],[Data_resolução]]=0,"",Relatorio_[[#This Row],[Data_resolução]]) | G8: Parcelamento Renovação - Dal Comercio Ltda | H8: Silvia S. | I8: Novo | J8: OTC | L8: - | M8: 1 | O8: ="INSERT INTO octadesk.stickets ("&$B$1&","&$D$1&","&$F$1&","&$G$1&","&$H$1&","&$I$1&","&$J$1&","&$K$1&","&$L$1&","&$M$1&") values("&IF(B8="","NULL","'"&B8&"'")&",'"&TEXT(D8,"aaaa-mm-dd hh:mm:ss")&"',"&IF(E8="","NULL","'"&TEXT(E8,"aaaa-mm-dd hh:mm:ss")&"'")&","&IF(G8="","NULL","'"&G8&"'")&","&IF(H8="","NULL","'"&H8&"'")&","&IF(I8="","NULL","'"&I8&"'")&","&IF(J8="","NULL","'"&J8&"'")&","&IF(K8="","NULL","'"&K8&"'")&","&IF(L8="","NULL","'"&L8&"'")&","&IF(M8="","NULL","'"&M8&"'")&");" -> INSERT INTO octadesk.stickets (ticket,Data_entrada,Data_resolucao,Titulo_ticket,Usuario_criador_ticket,Status,Grupo_responsavel,Responsavel_ticket,Tags_ticket,Total_de_interacoes) values('193146','2025-04-30 10:09:28',NULL,'Parcelamento Renovação - Dal Comercio Ltda','Silvia S.','Novo','OTC',NULL,'-','1');
B9: 193147 | C9: =IFERROR(VLOOKUP(Relatorio_[[#This Row],[ticket]],Base!A:A,1,0),"-") -> 193147 | D9: 45777.431 | E9: 45777.485 | F9: =IF(Relatorio_[[#This Row],[Data_resolução]]=0,"",Relatorio_[[#This Row],[Data_resolução]]) -> 45777.485 | G9: OCTADESCK 173521 NF | H9: Naiara Debia | I9: Resolvido | J9: Financeiro | L9: - | M9: 2 | O9: ="INSERT INTO octadesk.stickets ("&$B$1&","&$D$1&","&$F$1&","&$G$1&","&$H$1&","&$I$1&","&$J$1&","&$K$1&","&$L$1&","&$M$1&") values("&IF(B9="","NULL","'"&B9&"'")&",'"&TEXT(D9,"aaaa-mm-dd hh:mm:ss")&"',"&IF(E9="","NULL","'"&TEXT(E9,"aaaa-mm-dd hh:mm:ss")&"'")&","&IF(G9="","NULL","'"&G9&"'")&","&IF(H9="","NULL","'"&H9&"'")&","&IF(I9="","NULL","'"&I9&"'")&","&IF(J9="","NULL","'"&J9&"'")&","&IF(K9="","NULL","'"&K9&"'")&","&IF(L9="","NULL","'"&L9&"'")&","&IF(M9="","NULL","'"&M9&"'")&");" -> INSERT INTO octadesk.stickets (ticket,Data_entrada,Data_resolucao,Titulo_ticket,Usuario_criador_ticket,Status,Grupo_responsavel,Responsavel_ticket,Tags_ticket,Total_de_interacoes) values('193147','2025-04-30 10:20:04','2025-04-30 11:38:11','OCTADESCK 173521 NF','Naiara Debia','Resolvido','Financeiro',NULL,'-','2');
B10: 193148 | C10: =IFERROR(VLOOKUP(Relatorio_[[#This Row],[ticket]],Base!A:A,1,0),"-") -> 193148 | D10: 45777.436 | F10: =IF(Relatorio_[[#This Row],[Data_resolução]]=0,"",Relatorio_[[#This Row],[Data_resolução]]) | G10: Solicitação de suporte interno | H10: Suporte Octadesk | I10: Em andamento | J10: Suporte | K10: Brenda | L10: suporte-interno | M10: 2 | O10: ="INSERT INTO octadesk.stickets ("&$B$1&","&$D$1&","&$F$1&","&$G$1&","&$H$1&","&$I$1&","&$J$1&","&$K$1&","&$L$1&","&$M$1&") values("&IF(B10="","NULL","'"&B10&"'")&",'"&TEXT(D10,"aaaa-mm-dd hh:mm:ss")&"',"&IF(E10="","NULL","'"&TEXT(E10,"aaaa-mm-dd hh:mm:ss")&"'")&","&IF(G10="","NULL","'"&G10&"'")&","&IF(H10="","NULL","'"&H10&"'")&","&IF(I10="","NULL","'"&I10&"'")&","&IF(J10="","NULL","'"&J10&"'")&","&IF(K10="","NULL","'"&K10&"'")&","&IF(L10="","NULL","'"&L10&"'")&","&IF(M10="","NULL","'"&M10&"'")&");" -> INSERT INTO octadesk.stickets (ticket,Data_entrada,Data_resolucao,Titulo_ticket,Usuario_criador_ticket,Status,Grupo_responsavel,Responsavel_ticket,Tags_ticket,Total_de_interacoes) values('193148','2025-04-30 10:28:26',NULL,'Solicitação de suporte interno','Suporte Octadesk','Em andamento','Suporte','Brenda','suporte-interno','2');
B11: 193149 | C11: =IFERROR(VLOOKUP(Relatorio_[[#This Row],[ticket]],Base!A:A,1,0),"-") -> 193149 | D11: 45777.44 | E11: 45777.445 | F11: =IF(Relatorio_[[#This Row],[Data_resolução]]=0,"",Relatorio_[[#This Row],[Data_resolução]]) -> 45777.445 | G11: [Solicitação recebida] | H11: Support | I11: Cancelado | J11: Suporte | K11: Brenda | L11: - | M11: 2 | O11: ="INSERT INTO octadesk.stickets ("&$B$1&","&$D$1&","&$F$1&","&$G$1&","&$H$1&","&$I$1&","&$J$1&","&$K$1&","&$L$1&","&$M$1&") values("&IF(B11="","NULL","'"&B11&"'")&",'"&TEXT(D11,"aaaa-mm-dd hh:mm:ss")&"',"&IF(E11="","NULL","'"&TEXT(E11,"aaaa-mm-dd hh:mm:ss")&"'")&","&IF(G11="","NULL","'"&G11&"'")&","&IF(H11="","NULL","'"&H11&"'")&","&IF(I11="","NULL","'"&I11&"'")&","&IF(J11="","NULL","'"&J11&"'")&","&IF(K11="","NULL","'"&K11&"'")&","&IF(L11="","NULL","'"&L11&"'")&","&IF(M11="","NULL","'"&M11&"'")&");" -> INSERT INTO octadesk.stickets (ticket,Data_entrada,Data_resolucao,Titulo_ticket,Usuario_criador_ticket,Status,Grupo_responsavel,Responsavel_ticket,Tags_ticket,Total_de_interacoes) values('193149','2025-04-30 10:34:15','2025-04-30 10:40:46','[Solicitação recebida]','Support','Cancelado','Suporte','Brenda','-','2');
B12: 193150 | C12: =IFERROR(VLOOKUP(Relatorio_[[#This Row],[ticket]],Base!A:A,1,0),"-") -> 193150 | D12: 45777.441 | E12: 45777.445 | F12: =IF(Relatorio_[[#This Row],[Data_resolução]]=0,"",Relatorio_[[#This Row],[Data_resolução]]) -> 45777.445 | G12: [Solicitação recebida] | H12: Support | I12: Cancelado | J12: Suporte | K12: Brenda | L12: - | M12: 2 | O12: ="INSERT INTO octadesk.stickets ("&$B$1&","&$D$1&","&$F$1&","&$G$1&","&$H$1&","&$I$1&","&$J$1&","&$K$1&","&$L$1&","&$M$1&") values("&IF(B12="","NULL","'"&B12&"'")&",'"&TEXT(D12,"aaaa-mm-dd hh:mm:ss")&"',"&IF(E12="","NULL","'"&TEXT(E12,"aaaa-mm-dd hh:mm:ss")&"'")&","&IF(G12="","NULL","'"&G12&"'")&","&IF(H12="","NULL","'"&H12&"'")&","&IF(I12="","NULL","'"&I12&"'")&","&IF(J12="","NULL","'"&J12&"'")&","&IF(K12="","NULL","'"&K12&"'")&","&IF(L12="","NULL","'"&L12&"'")&","&IF(M12="","NULL","'"&M12&"'")&");" -> INSERT INTO octadesk.stickets (ticket,Data_entrada,Data_resolucao,Titulo_ticket,Usuario_criador_ticket,Status,Grupo_responsavel,Responsavel_ticket,Tags_ticket,Total_de_interacoes) values('193150','2025-04-30 10:34:21','2025-04-30 10:40:46','[Solicitação recebida]','Support','Cancelado','Suporte','Brenda','-','2');
B13: 193151 | C13: =IFERROR(VLOOKUP(Relatorio_[[#This Row],[ticket]],Base!A:A,1,0),"-") -> 193151 | D13: 45777.441 | E13: 45777.445 | F13: =IF(Relatorio_[[#This Row],[Data_resolução]]=0,"",Relatorio_[[#This Row],[Data_resolução]]) -> 45777.445 | G13: [Solicitação recebida] | H13: Support | I13: Cancelado | J13: Suporte | K13: Brenda | L13: - | M13: 2 | O13: ="INSERT INTO octadesk.stickets ("&$B$1&","&$D$1&","&$F$1&","&$G$1&","&$H$1&","&$I$1&","&$J$1&","&$K$1&","&$L$1&","&$M$1&") values("&IF(B13="","NULL","'"&B13&"'")&",'"&TEXT(D13,"aaaa-mm-dd hh:mm:ss")&"',"&IF(E13="","NULL","'"&TEXT(E13,"aaaa-mm-dd hh:mm:ss")&"'")&","&IF(G13="","NULL","'"&G13&"'")&","&IF(H13="","NULL","'"&H13&"'")&","&IF(I13="","NULL","'"&I13&"'")&","&IF(J13="","NULL","'"&J13&"'")&","&IF(K13="","NULL","'"&K13&"'")&","&IF(L13="","NULL","'"&L13&"'")&","&IF(M13="","NULL","'"&M13&"'")&");" -> INSERT INTO octadesk.stickets (ticket,Data_entrada,Data_resolucao,Titulo_ticket,Usuario_criador_ticket,Status,Grupo_responsavel,Responsavel_ticket,Tags_ticket,Total_de_interacoes) values('193151','2025-04-30 10:34:23','2025-04-30 10:40:46','[Solicitação recebida]','Support','Cancelado','Suporte','Brenda','-','2');
B14: 193152 | C14: =IFERROR(VLOOKUP(Relatorio_[[#This Row],[ticket]],Base!A:A,1,0),"-") -> 193152 | D14: 45777.441 | E14: 45777.445 | F14: =IF(Relatorio_[[#This Row],[Data_resolução]]=0,"",Relatorio_[[#This Row],[Data_resolução]]) -> 45777.445 | G14: [Solicitação recebida] | H14: Support | I14: Cancelado | J14: Suporte | K14: Brenda | L14: - | M14: 2 | O14: ="INSERT INTO octadesk.stickets ("&$B$1&","&$D$1&","&$F$1&","&$G$1&","&$H$1&","&$I$1&","&$J$1&","&$K$1&","&$L$1&","&$M$1&") values("&IF(B14="","NULL","'"&B14&"'")&",'"&TEXT(D14,"aaaa-mm-dd hh:mm:ss")&"',"&IF(E14="","NULL","'"&TEXT(E14,"aaaa-mm-dd hh:mm:ss")&"'")&","&IF(G14="","NULL","'"&G14&"'")&","&IF(H14="","NULL","'"&H14&"'")&","&IF(I14="","NULL","'"&I14&"'")&","&IF(J14="","NULL","'"&J14&"'")&","&IF(K14="","NULL","'"&K14&"'")&","&IF(L14="","NULL","'"&L14&"'")&","&IF(M14="","NULL","'"&M14&"'")&");" -> INSERT INTO octadesk.stickets (ticket,Data_entrada,Data_resolucao,Titulo_ticket,Usuario_criador_ticket,Status,Grupo_responsavel,Responsavel_ticket,Tags_ticket,Total_de_interacoes) values('193152','2025-04-30 10:34:27','2025-04-30 10:40:46','[Solicitação recebida]','Support','Cancelado','Suporte','Brenda','-','2');
B15: 193153 | C15: =IFERROR(VLOOKUP(Relatorio_[[#This Row],[ticket]],Base!A:A,1,0),"-") -> 193153 | D15: 45777.441 | E15: 45777.445 | F15: =IF(Relatorio_[[#This Row],[Data_resolução]]=0,"",Relatorio_[[#This Row],[Data_resolução]]) -> 45777.445 | G15: [Solicitação recebida] | H15: Support | I15: Cancelado | J15: Suporte | K15: Brenda | L15: - | M15: 2 | O15: ="INSERT INTO octadesk.stickets ("&$B$1&","&$D$1&","&$F$1&","&$G$1&","&$H$1&","&$I$1&","&$J$1&","&$K$1&","&$L$1&","&$M$1&") values("&IF(B15="","NULL","'"&B15&"'")&",'"&TEXT(D15,"aaaa-mm-dd hh:mm:ss")&"',"&IF(E15="","NULL","'"&TEXT(E15,"aaaa-mm-dd hh:mm:ss")&"'")&","&IF(G15="","NULL","'"&G15&"'")&","&IF(H15="","NULL","'"&H15&"'")&","&IF(I15="","NULL","'"&I15&"'")&","&IF(J15="","NULL","'"&J15&"'")&","&IF(K15="","NULL","'"&K15&"'")&","&IF(L15="","NULL","'"&L15&"'")&","&IF(M15="","NULL","'"&M15&"'")&");" -> INSERT INTO octadesk.stickets (ticket,Data_entrada,Data_resolucao,Titulo_ticket,Usuario_criador_ticket,Status,Grupo_responsavel,Responsavel_ticket,Tags_ticket,Total_de_interacoes) values('193153','2025-04-30 10:34:36','2025-04-30 10:40:46','[Solicitação recebida]','Support','Cancelado','Suporte','Brenda','-','2');
B16: 193154 | C16: =IFERROR(VLOOKUP(Relatorio_[[#This Row],[ticket]],Base!A:A,1,0),"-") -> 193154 | D16: 45777.441 | E16: 45777.445 | F16: =IF(Relatorio_[[#This Row],[Data_resolução]]=0,"",Relatorio_[[#This Row],[Data_resolução]]) -> 45777.445 | G16: [Solicitação recebida] | H16: Support | I16: Cancelado | J16: Suporte | K16: Brenda | L16: - | M16: 2 | O16: ="INSERT INTO octadesk.stickets ("&$B$1&","&$D$1&","&$F$1&","&$G$1&","&$H$1&","&$I$1&","&$J$1&","&$K$1&","&$L$1&","&$M$1&") values("&IF(B16="","NULL","'"&B16&"'")&",'"&TEXT(D16,"aaaa-mm-dd hh:mm:ss")&"',"&IF(E16="","NULL","'"&TEXT(E16,"aaaa-mm-dd hh:mm:ss")&"'")&","&IF(G16="","NULL","'"&G16&"'")&","&IF(H16="","NULL","'"&H16&"'")&","&IF(I16="","NULL","'"&I16&"'")&","&IF(J16="","NULL","'"&J16&"'")&","&IF(K16="","NULL","'"&K16&"'")&","&IF(L16="","NULL","'"&L16&"'")&","&IF(M16="","NULL","'"&M16&"'")&");" -> INSERT INTO octadesk.stickets (ticket,Data_entrada,Data_resolucao,Titulo_ticket,Usuario_criador_ticket,Status,Grupo_responsavel,Responsavel_ticket,Tags_ticket,Total_de_interacoes) values('193154','2025-04-30 10:34:40','2025-04-30 10:40:46','[Solicitação recebida]','Support','Cancelado','Suporte','Brenda','-','2');
B17: 193155 | C17: =IFERROR(VLOOKUP(Relatorio_[[#This Row],[ticket]],Base!A:A,1,0),"-") -> 193155 | D17: 45777.441 | E17: 45777.445 | F17: =IF(Relatorio_[[#This Row],[Data_resolução]]=0,"",Relatorio_[[#This Row],[Data_resolução]]) -> 45777.445 | G17: [Solicitação recebida] | H17: Support | I17: Cancelado | J17: Suporte | K17: Brenda | L17: - | M17: 2 | O17: ="INSERT INTO octadesk.stickets ("&$B$1&","&$D$1&","&$F$1&","&$G$1&","&$H$1&","&$I$1&","&$J$1&","&$K$1&","&$L$1&","&$M$1&") values("&IF(B17="","NULL","'"&B17&"'")&",'"&TEXT(D17,"aaaa-mm-dd hh:mm:ss")&"',"&IF(E17="","NULL","'"&TEXT(E17,"aaaa-mm-dd hh:mm:ss")&"'")&","&IF(G17="","NULL","'"&G17&"'")&","&IF(H17="","NULL","'"&H17&"'")&","&IF(I17="","NULL","'"&I17&"'")&","&IF(J17="","NULL","'"&J17&"'")&","&IF(K17="","NULL","'"&K17&"'")&","&IF(L17="","NULL","'"&L17&"'")&","&IF(M17="","NULL","'"&M17&"'")&");" -> INSERT INTO octadesk.stickets (ticket,Data_entrada,Data_resolucao,Titulo_ticket,Usuario_criador_ticket,Status,Grupo_responsavel,Responsavel_ticket,Tags_ticket,Total_de_interacoes) values('193155','2025-04-30 10:35:12','2025-04-30 10:40:46','[Solicitação recebida]','Support','Cancelado','Suporte','Brenda','-','2');
B18: 193156 | C18: =IFERROR(VLOOKUP(Relatorio_[[#This Row],[ticket]],Base!A:A,1,0),"-") -> 193156 | D18: 45777.441 | E18: 45777.445 | F18: =IF(Relatorio_[[#This Row],[Data_resolução]]=0,"",Relatorio_[[#This Row],[Data_resolução]]) -> 45777.445 | G18: [Solicitação recebida] | H18: Support | I18: Cancelado | J18: Suporte | K18: Brenda | L18: - | M18: 2 | O18: ="INSERT INTO octadesk.stickets ("&$B$1&","&$D$1&","&$F$1&","&$G$1&","&$H$1&","&$I$1&","&$J$1&","&$K$1&","&$L$1&","&$M$1&") values("&IF(B18="","NULL","'"&B18&"'")&",'"&TEXT(D18,"aaaa-mm-dd hh:mm:ss")&"',"&IF(E18="","NULL","'"&TEXT(E18,"aaaa-mm-dd hh:mm:ss")&"'")&","&IF(G18="","NULL","'"&G18&"'")&","&IF(H18="","NULL","'"&H18&"'")&","&IF(I18="","NULL","'"&I18&"'")&","&IF(J18="","NULL","'"&J18&"'")&","&IF(K18="","NULL","'"&K18&"'")&","&IF(L18="","NULL","'"&L18&"'")&","&IF(M18="","NULL","'"&M18&"'")&");" -> INSERT INTO octadesk.stickets (ticket,Data_entrada,Data_resolucao,Titulo_ticket,Usuario_criador_ticket,Status,Grupo_responsavel,Responsavel_ticket,Tags_ticket,Total_de_interacoes) values('193156','2025-04-30 10:35:16','2025-04-30 10:40:46','[Solicitação recebida]','Support','Cancelado','Suporte','Brenda','-','2');
B19: 193157 | C19: =IFERROR(VLOOKUP(Relatorio_[[#This Row],[ticket]],Base!A:A,1,0),"-") -> 193157 | D19: 45777.441 | E19: 45777.445 | F19: =IF(Relatorio_[[#This Row],[Data_resolução]]=0,"",Relatorio_[[#This Row],[Data_resolução]]) -> 45777.445 | G19: [Solicitação recebida] | H19: Support | I19: Cancelado | J19: Suporte | K19: Brenda | L19: - | M19: 2 | O19: ="INSERT INTO octadesk.stickets ("&$B$1&","&$D$1&","&$F$1&","&$G$1&","&$H$1&","&$I$1&","&$J$1&","&$K$1&","&$L$1&","&$M$1&") values("&IF(B19="","NULL","'"&B19&"'")&",'"&TEXT(D19,"aaaa-mm-dd hh:mm:ss")&"',"&IF(E19="","NULL","'"&TEXT(E19,"aaaa-mm-dd hh:mm:ss")&"'")&","&IF(G19="","NULL","'"&G19&"'")&","&IF(H19="","NULL","'"&H19&"'")&","&IF(I19="","NULL","'"&I19&"'")&","&IF(J19="","NULL","'"&J19&"'")&","&IF(K19="","NULL","'"&K19&"'")&","&IF(L19="","NULL","'"&L19&"'")&","&IF(M19="","NULL","'"&M19&"'")&");" -> INSERT INTO octadesk.stickets (ticket,Data_entrada,Data_resolucao,Titulo_ticket,Usuario_criador_ticket,Status,Grupo_responsavel,Responsavel_ticket,Tags_ticket,Total_de_interacoes) values('193157','2025-04-30 10:35:25','2025-04-30 10:40:46','[Solicitação recebida]','Support','Cancelado','Suporte','Brenda','-','2');
B20: 193158 | C20: =IFERROR(VLOOKUP(Relatorio_[[#This Row],[ticket]],Base!A:A,1,0),"-") -> 193158 | D20: 45777.444 | E20: 45779.438 | F20: =IF(Relatorio_[[#This Row],[Data_resolução]]=0,"",Relatorio_[[#This Row],[Data_resolução]]) -> 45779.438 | G20: Escalado por CS - o206726-bd7 | H20: Suporte Octadesk | I20: Cancelado | J20: N2 | K20: Juan C. | L20: suporte-interno | M20: 8 | O20: ="INSERT INTO octadesk.stickets ("&$B$1&","&$D$1&","&$F$1&","&$G$1&","&$H$1&","&$I$1&","&$J$1&","&$K$1&","&$L$1&","&$M$1&") values("&IF(B20="","NULL","'"&B20&"'")&",'"&TEXT(D20,"aaaa-mm-dd hh:mm:ss")&"',"&IF(E20="","NULL","'"&TEXT(E20,"aaaa-mm-dd hh:mm:ss")&"'")&","&IF(G20="","NULL","'"&G20&"'")&","&IF(H20="","NULL","'"&H20&"'")&","&IF(I20="","NULL","'"&I20&"'")&","&IF(J20="","NULL","'"&J20&"'")&","&IF(K20="","NULL","'"&K20&"'")&","&IF(L20="","NULL","'"&L20&"'")&","&IF(M20="","NULL","'"&M20&"'")&");" -> INSERT INTO octadesk.stickets (ticket,Data_entrada,Data_resolucao,Titulo_ticket,Usuario_criador_ticket,Status,Grupo_responsavel,Responsavel_ticket,Tags_ticket,Total_de_interacoes) values('193158','2025-04-30 10:38:39','2025-05-02 10:30:56','Escalado por CS - o206726-bd7','Suporte Octadesk','Cancelado','N2','Juan C.','suporte-interno','8');
B21: 193159 | C21: =IFERROR(VLOOKUP(Relatorio_[[#This Row],[ticket]],Base!A:A,1,0),"-") -> 193159 | D21: 45777.444 | F21: =IF(Relatorio_[[#This Row],[Data_resolução]]=0,"",Relatorio_[[#This Row],[Data_resolução]]) | G21: Erro na distribuição de conversas Wpp Web - drogalima | H21: Alberto | I21: Novo | J21: N2 | L21: chat | M21: 3 | O21: ="INSERT INTO octadesk.stickets ("&$B$1&","&$D$1&","&$F$1&","&$G$1&","&$H$1&","&$I$1&","&$J$1&","&$K$1&","&$L$1&","&$M$1&") values("&IF(B21="","NULL","'"&B21&"'")&",'"&TEXT(D21,"aaaa-mm-dd hh:mm:ss")&"',"&IF(E21="","NULL","'"&TEXT(E21,"aaaa-mm-dd hh:mm:ss")&"'")&","&IF(G21="","NULL","'"&G21&"'")&","&IF(H21="","NULL","'"&H21&"'")&","&IF(I21="","NULL","'"&I21&"'")&","&IF(J21="","NULL","'"&J21&"'")&","&IF(K21="","NULL","'"&K21&"'")&","&IF(L21="","NULL","'"&L21&"'")&","&IF(M21="","NULL","'"&M21&"'")&");" -> INSERT INTO octadesk.stickets (ticket,Data_entrada,Data_resolucao,Titulo_ticket,Usuario_criador_ticket,Status,Grupo_responsavel,Responsavel_ticket,Tags_ticket,Total_de_interacoes) values('193159','2025-04-30 10:40:03',NULL,'Erro na distribuição de conversas Wpp Web - drogalima','Alberto','Novo','N2',NULL,'chat','3');
B22: 193160 | C22: =IFERROR(VLOOKUP(Relatorio_[[#This Row],[ticket]],Base!A:A,1,0),"-") -> 193160 | D22: 45777.459 | E22: 45777.643 | F22: =IF(Relatorio_[[#This Row],[Data_resolução]]=0,"",Relatorio_[[#This Row],[Data_resolução]]) -> 45777.643 | G22: ❌ Não tem como vender mais se você prospecta leads ruins | H22: Talita da Speedio | I22: Cancelado | J22: Suporte | K22: Brenda | L22: - | M22: 2 | O22: ="INSERT INTO octadesk.stickets ("&$B$1&","&$D$1&","&$F$1&","&$G$1&","&$H$1&","&$I$1&","&$J$1&","&$K$1&","&$L$1&","&$M$1&") values("&IF(B22="","NULL","'"&B22&"'")&",'"&TEXT(D22,"aaaa-mm-dd hh:mm:ss")&"',"&IF(E22="","NULL","'"&TEXT(E22,"aaaa-mm-dd hh:mm:ss")&"'")&","&IF(G22="","NULL","'"&G22&"'")&","&IF(H22="","NULL","'"&H22&"'")&","&IF(I22="","NULL","'"&I22&"'")&","&IF(J22="","NULL","'"&J22&"'")&","&IF(K22="","NULL","'"&K22&"'")&","&IF(L22="","NULL","'"&L22&"'")&","&IF(M22="","NULL","'"&M22&"'")&");" -> INSERT INTO octadesk.stickets (ticket,Data_entrada,Data_resolucao,Titulo_ticket,Usuario_criador_ticket,Status,Grupo_responsavel,Responsavel_ticket,Tags_ticket,Total_de_interacoes) values('193160','2025-04-30 11:01:16','2025-04-30 15:26:07','❌ Não tem como vender mais se você prospecta leads ruins','Talita da Speedio','Cancelado','Suporte','Brenda','-','2');
B23: 193161 | C23: =IFERROR(VLOOKUP(Relatorio_[[#This Row],[ticket]],Base!A:A,1,0),"-") -> 193161 | D23: 45777.476 | F23: =IF(Relatorio_[[#This Row],[Data_resolução]]=0,"",Relatorio_[[#This Row],[Data_resolução]]) | G23: Não recebe notificação (email) de criação de tickets ou menção | H23: Mailon Dos Santos Sanches | I23: Em andamento | J23: N2 | L23: chat, problema-envio-email | M23: 7 | O23: ="INSERT INTO octadesk.stickets ("&$B$1&","&$D$1&","&$F$1&","&$G$1&","&$H$1&","&$I$1&","&$J$1&","&$K$1&","&$L$1&","&$M$1&") values("&IF(B23="","NULL","'"&B23&"'")&",'"&TEXT(D23,"aaaa-mm-dd hh:mm:ss")&"',"&IF(E23="","NULL","'"&TEXT(E23,"aaaa-mm-dd hh:mm:ss")&"'")&","&IF(G23="","NULL","'"&G23&"'")&","&IF(H23="","NULL","'"&H23&"'")&","&IF(I23="","NULL","'"&I23&"'")&","&IF(J23="","NULL","'"&J23&"'")&","&IF(K23="","NULL","'"&K23&"'")&","&IF(L23="","NULL","'"&L23&"'")&","&IF(M23="","NULL","'"&M23&"'")&");" -> INSERT INTO octadesk.stickets (ticket,Data_entrada,Data_resolucao,Titulo_ticket,Usuario_criador_ticket,Status,Grupo_responsavel,Responsavel_ticket,Tags_ticket,Total_de_interacoes) values('193161','2025-04-30 11:26:09',NULL,'Não recebe notificação (email) de criação de tickets ou menção','Mailon Dos Santos Sanches','Em andamento','N2',NULL,'chat, problema-envio-email','7');
B24: 193162 | C24: =IFERROR(VLOOKUP(Relatorio_[[#This Row],[ticket]],Base!A:A,1,0),"-") -> 193162 | D24: 45777.501 | F24: =IF(Relatorio_[[#This Row],[Data_resolução]]=0,"",Relatorio_[[#This Row],[Data_resolução]]) | G24: SOLICITAÇÃO DE BACKUP - CONVERSAS E CONTATOS | H24: Eduarda | I24: Pendente | J24: Suporte | K24: Brenda | L24: automacao-24horas | M24: 2 | O24: ="INSERT INTO octadesk.stickets ("&$B$1&","&$D$1&","&$F$1&","&$G$1&","&$H$1&","&$I$1&","&$J$1&","&$K$1&","&$L$1&","&$M$1&") values("&IF(B24="","NULL","'"&B24&"'")&",'"&TEXT(D24,"aaaa-mm-dd hh:mm:ss")&"',"&IF(E24="","NULL","'"&TEXT(E24,"aaaa-mm-dd hh:mm:ss")&"'")&","&IF(G24="","NULL","'"&G24&"'")&","&IF(H24="","NULL","'"&H24&"'")&","&IF(I24="","NULL","'"&I24&"'")&","&IF(J24="","NULL","'"&J24&"'")&","&IF(K24="","NULL","'"&K24&"'")&","&IF(L24="","NULL","'"&L24&"'")&","&IF(M24="","NULL","'"&M24&"'")&");" -> INSERT INTO octadesk.stickets (ticket,Data_entrada,Data_resolucao,Titulo_ticket,Usuario_criador_ticket,Status,Grupo_responsavel,Responsavel_ticket,Tags_ticket,Total_de_interacoes) values('193162','2025-04-30 12:01:50',NULL,'SOLICITAÇÃO DE BACKUP - CONVERSAS E CONTATOS','Eduarda','Pendente','Suporte','Brenda','automacao-24horas','2');
B25: 193163 | C25: =IFERROR(VLOOKUP(Relatorio_[[#This Row],[ticket]],Base!A:A,1,0),"-") -> 193163 | D25: 45777.505 | E25: 45779.732 | F25: =IF(Relatorio_[[#This Row],[Data_resolução]]=0,"",Relatorio_[[#This Row],[Data_resolução]]) -> 45779.732 | G25: Não entrou os créditos mensais - o179888-c27 | H25: MARCELA ROCHA | I25: Cancelado | J25: N2 | L25: chat | M25: 13 | O25: ="INSERT INTO octadesk.stickets ("&$B$1&","&$D$1&","&$F$1&","&$G$1&","&$H$1&","&$I$1&","&$J$1&","&$K$1&","&$L$1&","&$M$1&") values("&IF(B25="","NULL","'"&B25&"'")&",'"&TEXT(D25,"aaaa-mm-dd hh:mm:ss")&"',"&IF(E25="","NULL","'"&TEXT(E25,"aaaa-mm-dd hh:mm:ss")&"'")&","&IF(G25="","NULL","'"&G25&"'")&","&IF(H25="","NULL","'"&H25&"'")&","&IF(I25="","NULL","'"&I25&"'")&","&IF(J25="","NULL","'"&J25&"'")&","&IF(K25="","NULL","'"&K25&"'")&","&IF(L25="","NULL","'"&L25&"'")&","&IF(M25="","NULL","'"&M25&"'")&");" -> INSERT INTO octadesk.stickets (ticket,Data_entrada,Data_resolucao,Titulo_ticket,Usuario_criador_ticket,Status,Grupo_responsavel,Responsavel_ticket,Tags_ticket,Total_de_interacoes) values('193163','2025-04-30 12:07:14','2025-05-02 17:34:13','Não entrou os créditos mensais - o179888-c27','MARCELA ROCHA','Cancelado','N2',NULL,'chat','13');
B26: 193164 | C26: =IFERROR(VLOOKUP(Relatorio_[[#This Row],[ticket]],Base!A:A,1,0),"-") -> 193164 | D26: 45777.506 | E26: 45777.516 | F26: =IF(Relatorio_[[#This Row],[Data_resolução]]=0,"",Relatorio_[[#This Row],[Data_resolução]]) -> 45777.516 | G26: Customer, ofertas especiais para sua empresa | H26: Lenovo Brasil | I26: Cancelado | J26: Financeiro | L26: - | M26: 2 | O26: ="INSERT INTO octadesk.stickets ("&$B$1&","&$D$1&","&$F$1&","&$G$1&","&$H$1&","&$I$1&","&$J$1&","&$K$1&","&$L$1&","&$M$1&") values("&IF(B26="","NULL","'"&B26&"'")&",'"&TEXT(D26,"aaaa-mm-dd hh:mm:ss")&"',"&IF(E26="","NULL","'"&TEXT(E26,"aaaa-mm-dd hh:mm:ss")&"'")&","&IF(G26="","NULL","'"&G26&"'")&","&IF(H26="","NULL","'"&H26&"'")&","&IF(I26="","NULL","'"&I26&"'")&","&IF(J26="","NULL","'"&J26&"'")&","&IF(K26="","NULL","'"&K26&"'")&","&IF(L26="","NULL","'"&L26&"'")&","&IF(M26="","NULL","'"&M26&"'")&");" -> INSERT INTO octadesk.stickets (ticket,Data_entrada,Data_resolucao,Titulo_ticket,Usuario_criador_ticket,Status,Grupo_responsavel,Responsavel_ticket,Tags_ticket,Total_de_interacoes) values('193164','2025-04-30 12:08:36','2025-04-30 12:22:43','Customer, ofertas especiais para sua empresa','Lenovo Brasil','Cancelado','Financeiro',NULL,'-','2');
B27: 193165 | C27: =IFERROR(VLOOKUP(Relatorio_[[#This Row],[ticket]],Base!A:A,1,0),"-") -> 193165 | D27: 45777.536 | F27: =IF(Relatorio_[[#This Row],[Data_resolução]]=0,"",Relatorio_[[#This Row],[Data_resolução]]) | G27: PROD - Octa-Conversas - Bug visual na variável em componentes do bot - Vários ambientes | H27: Juan C. | I27: Novo | J27: PROD - Octa-Conversas | K27: Juliana Wilcke | L27: 192862 | M27: 3 | O27: ="INSERT INTO octadesk.stickets ("&$B$1&","&$D$1&","&$F$1&","&$G$1&","&$H$1&","&$I$1&","&$J$1&","&$K$1&","&$L$1&","&$M$1&") values("&IF(B27="","NULL","'"&B27&"'")&",'"&TEXT(D27,"aaaa-mm-dd hh:mm:ss")&"',"&IF(E27="","NULL","'"&TEXT(E27,"aaaa-mm-dd hh:mm:ss")&"'")&","&IF(G27="","NULL","'"&G27&"'")&","&IF(H27="","NULL","'"&H27&"'")&","&IF(I27="","NULL","'"&I27&"'")&","&IF(J27="","NULL","'"&J27&"'")&","&IF(K27="","NULL","'"&K27&"'")&","&IF(L27="","NULL","'"&L27&"'")&","&IF(M27="","NULL","'"&M27&"'")&");" -> INSERT INTO octadesk.stickets (ticket,Data_entrada,Data_resolucao,Titulo_ticket,Usuario_criador_ticket,Status,Grupo_responsavel,Responsavel_ticket,Tags_ticket,Total_de_interacoes) values('193165','2025-04-30 12:51:45',NULL,'PROD - Octa-Conversas - Bug visual na variável em componentes do bot - Vários ambientes','Juan C.','Novo','PROD - Octa-Conversas','Juliana Wilcke','192862','3');
B28: 193166 | C28: =IFERROR(VLOOKUP(Relatorio_[[#This Row],[ticket]],Base!A:A,1,0),"-") -> 193166 | D28: 45777.54 | F28: =IF(Relatorio_[[#This Row],[Data_resolução]]=0,"",Relatorio_[[#This Row],[Data_resolução]]) | G28: Erro atribuir responsável endpoint API - o157076-d18 | H28: Flai Silva Lino | I28: Novo | J28: N2 | L28: - | M28: 3 | O28: ="INSERT INTO octadesk.stickets ("&$B$1&","&$D$1&","&$F$1&","&$G$1&","&$H$1&","&$I$1&","&$J$1&","&$K$1&","&$L$1&","&$M$1&") values("&IF(B28="","NULL","'"&B28&"'")&",'"&TEXT(D28,"aaaa-mm-dd hh:mm:ss")&"',"&IF(E28="","NULL","'"&TEXT(E28,"aaaa-mm-dd hh:mm:ss")&"'")&","&IF(G28="","NULL","'"&G28&"'")&","&IF(H28="","NULL","'"&H28&"'")&","&IF(I28="","NULL","'"&I28&"'")&","&IF(J28="","NULL","'"&J28&"'")&","&IF(K28="","NULL","'"&K28&"'")&","&IF(L28="","NULL","'"&L28&"'")&","&IF(M28="","NULL","'"&M28&"'")&");" -> INSERT INTO octadesk.stickets (ticket,Data_entrada,Data_resolucao,Titulo_ticket,Usuario_criador_ticket,Status,Grupo_responsavel,Responsavel_ticket,Tags_ticket,Total_de_interacoes) values('193166','2025-04-30 12:58:00',NULL,'Erro atribuir responsável endpoint API - o157076-d18','Flai Silva Lino','Novo','N2',NULL,'-','3');
B29: 193167 | C29: =IFERROR(VLOOKUP(Relatorio_[[#This Row],[ticket]],Base!A:A,1,0),"-") -> 193167 | D29: 45777.559 | E29: 45778.597 | F29: =IF(Relatorio_[[#This Row],[Data_resolução]]=0,"",Relatorio_[[#This Row],[Data_resolução]]) -> 45778.597 | G29: Backup do historico de conversas - o148872-a4a | H29: Flávia | I29: Resolvido | J29: N2 | K29: Juan C. | L29: chat, problema-envio-email | M29: 11 | O29: ="INSERT INTO octadesk.stickets ("&$B$1&","&$D$1&","&$F$1&","&$G$1&","&$H$1&","&$I$1&","&$J$1&","&$K$1&","&$L$1&","&$M$1&") values("&IF(B29="","NULL","'"&B29&"'")&",'"&TEXT(D29,"aaaa-mm-dd hh:mm:ss")&"',"&IF(E29="","NULL","'"&TEXT(E29,"aaaa-mm-dd hh:mm:ss")&"'")&","&IF(G29="","NULL","'"&G29&"'")&","&IF(H29="","NULL","'"&H29&"'")&","&IF(I29="","NULL","'"&I29&"'")&","&IF(J29="","NULL","'"&J29&"'")&","&IF(K29="","NULL","'"&K29&"'")&","&IF(L29="","NULL","'"&L29&"'")&","&IF(M29="","NULL","'"&M29&"'")&");" -> INSERT INTO octadesk.stickets (ticket,Data_entrada,Data_resolucao,Titulo_ticket,Usuario_criador_ticket,Status,Grupo_responsavel,Responsavel_ticket,Tags_ticket,Total_de_interacoes) values('193167','2025-04-30 13:25:12','2025-05-01 14:19:21','Backup do historico de conversas - o148872-a4a','Flávia','Resolvido','N2','Juan C.','chat, problema-envio-email','11');
B30: 193168 | C30: =IFERROR(VLOOKUP(Relatorio_[[#This Row],[ticket]],Base!A:A,1,0),"-") -> 193168 | D30: 45777.578 | F30: =IF(Relatorio_[[#This Row],[Data_resolução]]=0,"",Relatorio_[[#This Row],[Data_resolução]]) | G30: Regarding your publication on octadesk.com | H30: COPYTRACK | I30: Novo | J30: Suporte | K30: Brenda | L30: - | M30: 1 | O30: ="INSERT INTO octadesk.stickets ("&$B$1&","&$D$1&","&$F$1&","&$G$1&","&$H$1&","&$I$1&","&$J$1&","&$K$1&","&$L$1&","&$M$1&") values("&IF(B30="","NULL","'"&B30&"'")&",'"&TEXT(D30,"aaaa-mm-dd hh:mm:ss")&"',"&IF(E30="","NULL","'"&TEXT(E30,"aaaa-mm-dd hh:mm:ss")&"'")&","&IF(G30="","NULL","'"&G30&"'")&","&IF(H30="","NULL","'"&H30&"'")&","&IF(I30="","NULL","'"&I30&"'")&","&IF(J30="","NULL","'"&J30&"'")&","&IF(K30="","NULL","'"&K30&"'")&","&IF(L30="","NULL","'"&L30&"'")&","&IF(M30="","NULL","'"&M30&"'")&");" -> INSERT INTO octadesk.stickets (ticket,Data_entrada,Data_resolucao,Titulo_ticket,Usuario_criador_ticket,Status,Grupo_responsavel,Responsavel_ticket,Tags_ticket,Total_de_interacoes) values('193168','2025-04-30 13:51:59',NULL,'Regarding your publication on octadesk.com','COPYTRACK','Novo','Suporte','Brenda','-','1');
B31: 193169 | C31: =IFERROR(VLOOKUP(Relatorio_[[#This Row],[ticket]],Base!A:A,1,0),"-") -> 193169 | D31: 45777.598 | E31: 45777.598 | F31: =IF(Relatorio_[[#This Row],[Data_resolução]]=0,"",Relatorio_[[#This Row],[Data_resolução]]) -> 45777.598 | G31: Retorno sobre recolhimento de Imposto. | H31: Mariana C. | I31: Resolvido | J31: Financeiro | L31: - | M31: 1 | O31: ="INSERT INTO octadesk.stickets ("&$B$1&","&$D$1&","&$F$1&","&$G$1&","&$H$1&","&$I$1&","&$J$1&","&$K$1&","&$L$1&","&$M$1&") values("&IF(B31="","NULL","'"&B31&"'")&",'"&TEXT(D31,"aaaa-mm-dd hh:mm:ss")&"',"&IF(E31="","NULL","'"&TEXT(E31,"aaaa-mm-dd hh:mm:ss")&"'")&","&IF(G31="","NULL","'"&G31&"'")&","&IF(H31="","NULL","'"&H31&"'")&","&IF(I31="","NULL","'"&I31&"'")&","&IF(J31="","NULL","'"&J31&"'")&","&IF(K31="","NULL","'"&K31&"'")&","&IF(L31="","NULL","'"&L31&"'")&","&IF(M31="","NULL","'"&M31&"'")&");" -> INSERT INTO octadesk.stickets (ticket,Data_entrada,Data_resolucao,Titulo_ticket,Usuario_criador_ticket,Status,Grupo_responsavel,Responsavel_ticket,Tags_ticket,Total_de_interacoes) values('193169','2025-04-30 14:21:04','2025-04-30 14:21:04','Retorno sobre recolhimento de Imposto.','Mariana C.','Resolvido','Financeiro',NULL,'-','1');
B32: 193170 | C32: =IFERROR(VLOOKUP(Relatorio_[[#This Row],[ticket]],Base!A:A,1,0),"-") -> 193170 | D32: 45777.605 | F32: =IF(Relatorio_[[#This Row],[Data_resolução]]=0,"",Relatorio_[[#This Row],[Data_resolução]]) | G32: (Confirmação de encaminhamento do LWSA: receber e-mail de ouvidoria@new.octadesk.com | H32: Gmail Equipe | I32: Novo | J32: Ouvidoria | K32: Mateus M. | L32: - | M32: 1 | O32: ="INSERT INTO octadesk.stickets ("&$B$1&","&$D$1&","&$F$1&","&$G$1&","&$H$1&","&$I$1&","&$J$1&","&$K$1&","&$L$1&","&$M$1&") values("&IF(B32="","NULL","'"&B32&"'")&",'"&TEXT(D32,"aaaa-mm-dd hh:mm:ss")&"',"&IF(E32="","NULL","'"&TEXT(E32,"aaaa-mm-dd hh:mm:ss")&"'")&","&IF(G32="","NULL","'"&G32&"'")&","&IF(H32="","NULL","'"&H32&"'")&","&IF(I32="","NULL","'"&I32&"'")&","&IF(J32="","NULL","'"&J32&"'")&","&IF(K32="","NULL","'"&K32&"'")&","&IF(L32="","NULL","'"&L32&"'")&","&IF(M32="","NULL","'"&M32&"'")&");" -> INSERT INTO octadesk.stickets (ticket,Data_entrada,Data_resolucao,Titulo_ticket,Usuario_criador_ticket,Status,Grupo_responsavel,Responsavel_ticket,Tags_ticket,Total_de_interacoes) values('193170','2025-04-30 14:30:57',NULL,'(Confirmação de encaminhamento do LWSA: receber e-mail de ouvidoria@new.octadesk.com','Gmail Equipe','Novo','Ouvidoria','Mateus M.','-','1');
B33: 193171 | C33: =IFERROR(VLOOKUP(Relatorio_[[#This Row],[ticket]],Base!A:A,1,0),"-") -> 193171 | D33: 45777.605 | E33: 45777.693 | F33: =IF(Relatorio_[[#This Row],[Data_resolução]]=0,"",Relatorio_[[#This Row],[Data_resolução]]) -> 45777.693 | G33: (Confirmação de encaminhamento do LWSA: receber e-mail de contasareceber@new.octadesk.com | H33: Gmail Equipe | I33: Resolvido | J33: Financeiro | L33: - | M33: 2 | O33: ="INSERT INTO octadesk.stickets ("&$B$1&","&$D$1&","&$F$1&","&$G$1&","&$H$1&","&$I$1&","&$J$1&","&$K$1&","&$L$1&","&$M$1&") values("&IF(B33="","NULL","'"&B33&"'")&",'"&TEXT(D33,"aaaa-mm-dd hh:mm:ss")&"',"&IF(E33="","NULL","'"&TEXT(E33,"aaaa-mm-dd hh:mm:ss")&"'")&","&IF(G33="","NULL","'"&G33&"'")&","&IF(H33="","NULL","'"&H33&"'")&","&IF(I33="","NULL","'"&I33&"'")&","&IF(J33="","NULL","'"&J33&"'")&","&IF(K33="","NULL","'"&K33&"'")&","&IF(L33="","NULL","'"&L33&"'")&","&IF(M33="","NULL","'"&M33&"'")&");" -> INSERT INTO octadesk.stickets (ticket,Data_entrada,Data_resolucao,Titulo_ticket,Usuario_criador_ticket,Status,Grupo_responsavel,Responsavel_ticket,Tags_ticket,Total_de_interacoes) values('193171','2025-04-30 14:31:28','2025-04-30 16:37:32','(Confirmação de encaminhamento do LWSA: receber e-mail de contasareceber@new.octadesk.com','Gmail Equipe','Resolvido','Financeiro',NULL,'-','2');
B34: 193172 | C34: =IFERROR(VLOOKUP(Relatorio_[[#This Row],[ticket]],Base!A:A,1,0),"-") -> 193172 | D34: 45777.614 | F34: =IF(Relatorio_[[#This Row],[Data_resolução]]=0,"",Relatorio_[[#This Row],[Data_resolução]]) | G34: Suporte - Tickets | H34: Gabriel - Gold Languages Traduções | I34: Pendente | J34: Suporte | K34: Brenda | L34: automacao-24horas | M34: 2 | O34: ="INSERT INTO octadesk.stickets ("&$B$1&","&$D$1&","&$F$1&","&$G$1&","&$H$1&","&$I$1&","&$J$1&","&$K$1&","&$L$1&","&$M$1&") values("&IF(B34="","NULL","'"&B34&"'")&",'"&TEXT(D34,"aaaa-mm-dd hh:mm:ss")&"',"&IF(E34="","NULL","'"&TEXT(E34,"aaaa-mm-dd hh:mm:ss")&"'")&","&IF(G34="","NULL","'"&G34&"'")&","&IF(H34="","NULL","'"&H34&"'")&","&IF(I34="","NULL","'"&I34&"'")&","&IF(J34="","NULL","'"&J34&"'")&","&IF(K34="","NULL","'"&K34&"'")&","&IF(L34="","NULL","'"&L34&"'")&","&IF(M34="","NULL","'"&M34&"'")&");" -> INSERT INTO octadesk.stickets (ticket,Data_entrada,Data_resolucao,Titulo_ticket,Usuario_criador_ticket,Status,Grupo_responsavel,Responsavel_ticket,Tags_ticket,Total_de_interacoes) values('193172','2025-04-30 14:44:44',NULL,'Suporte - Tickets','Gabriel - Gold Languages Traduções','Pendente','Suporte','Brenda','automacao-24horas','2');
B35: 193173 | C35: =IFERROR(VLOOKUP(Relatorio_[[#This Row],[ticket]],Base!A:A,1,0),"-") -> 193173 | D35: 45777.615 | F35: =IF(Relatorio_[[#This Row],[Data_resolução]]=0,"",Relatorio_[[#This Row],[Data_resolução]]) | G35: Erro ao alterar a atribuição dos tickets - o158707-351 | H35: Wilson | I35: Em andamento | J35: N2 | K35: Juan C. | L35: chat, problema-envio-email, 193194 | M35: 14 | O35: ="INSERT INTO octadesk.stickets ("&$B$1&","&$D$1&","&$F$1&","&$G$1&","&$H$1&","&$I$1&","&$J$1&","&$K$1&","&$L$1&","&$M$1&") values("&IF(B35="","NULL","'"&B35&"'")&",'"&TEXT(D35,"aaaa-mm-dd hh:mm:ss")&"',"&IF(E35="","NULL","'"&TEXT(E35,"aaaa-mm-dd hh:mm:ss")&"'")&","&IF(G35="","NULL","'"&G35&"'")&","&IF(H35="","NULL","'"&H35&"'")&","&IF(I35="","NULL","'"&I35&"'")&","&IF(J35="","NULL","'"&J35&"'")&","&IF(K35="","NULL","'"&K35&"'")&","&IF(L35="","NULL","'"&L35&"'")&","&IF(M35="","NULL","'"&M35&"'")&");" -> INSERT INTO octadesk.stickets (ticket,Data_entrada,Data_resolucao,Titulo_ticket,Usuario_criador_ticket,Status,Grupo_responsavel,Responsavel_ticket,Tags_ticket,Total_de_interacoes) values('193173','2025-04-30 14:45:16',NULL,'Erro ao alterar a atribuição dos tickets - o158707-351','Wilson','Em andamento','N2','Juan C.','chat, problema-envio-email, 193194','14');
B36: 193174 | C36: =IFERROR(VLOOKUP(Relatorio_[[#This Row],[ticket]],Base!A:A,1,0),"-") -> 193174 | D36: 45777.633 | F36: =IF(Relatorio_[[#This Row],[Data_resolução]]=0,"",Relatorio_[[#This Row],[Data_resolução]]) | G36: Reembolso - Brietzig Administracao E Corretagem De Imoveis | H36: Silvia S. | I36: Em andamento | J36: OTC | L36: - | M36: 2 | O36: ="INSERT INTO octadesk.stickets ("&$B$1&","&$D$1&","&$F$1&","&$G$1&","&$H$1&","&$I$1&","&$J$1&","&$K$1&","&$L$1&","&$M$1&") values("&IF(B36="","NULL","'"&B36&"'")&",'"&TEXT(D36,"aaaa-mm-dd hh:mm:ss")&"',"&IF(E36="","NULL","'"&TEXT(E36,"aaaa-mm-dd hh:mm:ss")&"'")&","&IF(G36="","NULL","'"&G36&"'")&","&IF(H36="","NULL","'"&H36&"'")&","&IF(I36="","NULL","'"&I36&"'")&","&IF(J36="","NULL","'"&J36&"'")&","&IF(K36="","NULL","'"&K36&"'")&","&IF(L36="","NULL","'"&L36&"'")&","&IF(M36="","NULL","'"&M36&"'")&");" -> INSERT INTO octadesk.stickets (ticket,Data_entrada,Data_resolucao,Titulo_ticket,Usuario_criador_ticket,Status,Grupo_responsavel,Responsavel_ticket,Tags_ticket,Total_de_interacoes) values('193174','2025-04-30 15:11:24',NULL,'Reembolso - Brietzig Administracao E Corretagem De Imoveis','Silvia S.','Em andamento','OTC',NULL,'-','2');
B37: 193175 | C37: =IFERROR(VLOOKUP(Relatorio_[[#This Row],[ticket]],Base!A:A,1,0),"-") -> 193175 | D37: 45777.633 | E37: 45777.644 | F37: =IF(Relatorio_[[#This Row],[Data_resolução]]=0,"",Relatorio_[[#This Row],[Data_resolução]]) -> 45777.644 | G37: Olá psi, aqui está nossa conversa! #15954 | H37: psi | I37: Cancelado | J37: Suporte | K37: Brenda | L37: - | M37: 2 | O37: ="INSERT INTO octadesk.stickets ("&$B$1&","&$D$1&","&$F$1&","&$G$1&","&$H$1&","&$I$1&","&$J$1&","&$K$1&","&$L$1&","&$M$1&") values("&IF(B37="","NULL","'"&B37&"'")&",'"&TEXT(D37,"aaaa-mm-dd hh:mm:ss")&"',"&IF(E37="","NULL","'"&TEXT(E37,"aaaa-mm-dd hh:mm:ss")&"'")&","&IF(G37="","NULL","'"&G37&"'")&","&IF(H37="","NULL","'"&H37&"'")&","&IF(I37="","NULL","'"&I37&"'")&","&IF(J37="","NULL","'"&J37&"'")&","&IF(K37="","NULL","'"&K37&"'")&","&IF(L37="","NULL","'"&L37&"'")&","&IF(M37="","NULL","'"&M37&"'")&");" -> INSERT INTO octadesk.stickets (ticket,Data_entrada,Data_resolucao,Titulo_ticket,Usuario_criador_ticket,Status,Grupo_responsavel,Responsavel_ticket,Tags_ticket,Total_de_interacoes) values('193175','2025-04-30 15:11:39','2025-04-30 15:26:57','Olá psi, aqui está nossa conversa! #15954','psi','Cancelado','Suporte','Brenda','-','2');
B38: 193176 | C38: =IFERROR(VLOOKUP(Relatorio_[[#This Row],[ticket]],Base!A:A,1,0),"-") -> 193176 | D38: 45777.633 | E38: 45777.644 | F38: =IF(Relatorio_[[#This Row],[Data_resolução]]=0,"",Relatorio_[[#This Row],[Data_resolução]]) -> 45777.644 | G38: Olá psi, aqui está nossa conversa! #15954 | H38: psi | I38: Cancelado | J38: Suporte | K38: Brenda | L38: - | M38: 2 | O38: ="INSERT INTO octadesk.stickets ("&$B$1&","&$D$1&","&$F$1&","&$G$1&","&$H$1&","&$I$1&","&$J$1&","&$K$1&","&$L$1&","&$M$1&") values("&IF(B38="","NULL","'"&B38&"'")&",'"&TEXT(D38,"aaaa-mm-dd hh:mm:ss")&"',"&IF(E38="","NULL","'"&TEXT(E38,"aaaa-mm-dd hh:mm:ss")&"'")&","&IF(G38="","NULL","'"&G38&"'")&","&IF(H38="","NULL","'"&H38&"'")&","&IF(I38="","NULL","'"&I38&"'")&","&IF(J38="","NULL","'"&J38&"'")&","&IF(K38="","NULL","'"&K38&"'")&","&IF(L38="","NULL","'"&L38&"'")&","&IF(M38="","NULL","'"&M38&"'")&");" -> INSERT INTO octadesk.stickets (ticket,Data_entrada,Data_resolucao,Titulo_ticket,Usuario_criador_ticket,Status,Grupo_responsavel,Responsavel_ticket,Tags_ticket,Total_de_interacoes) values('193176','2025-04-30 15:11:40','2025-04-30 15:26:46','Olá psi, aqui está nossa conversa! #15954','psi','Cancelado','Suporte','Brenda','-','2');
B39: 193177 | C39: =IFERROR(VLOOKUP(Relatorio_[[#This Row],[ticket]],Base!A:A,1,0),"-") -> 193177 | D39: 45777.638 | F39: =IF(Relatorio_[[#This Row],[Data_resolução]]=0,"",Relatorio_[[#This Row],[Data_resolução]]) | G39: Incidente - WOZ transcrição não está funcionando como deveria - o184072-481 | H39: Juan C. | I39: Pendente | J39: N2 | K39: Juan C. | L39: 193123, ticket-corrigido | M39: 4 | O39: ="INSERT INTO octadesk.stickets ("&$B$1&","&$D$1&","&$F$1&","&$G$1&","&$H$1&","&$I$1&","&$J$1&","&$K$1&","&$L$1&","&$M$1&") values("&IF(B39="","NULL","'"&B39&"'")&",'"&TEXT(D39,"aaaa-mm-dd hh:mm:ss")&"',"&IF(E39="","NULL","'"&TEXT(E39,"aaaa-mm-dd hh:mm:ss")&"'")&","&IF(G39="","NULL","'"&G39&"'")&","&IF(H39="","NULL","'"&H39&"'")&","&IF(I39="","NULL","'"&I39&"'")&","&IF(J39="","NULL","'"&J39&"'")&","&IF(K39="","NULL","'"&K39&"'")&","&IF(L39="","NULL","'"&L39&"'")&","&IF(M39="","NULL","'"&M39&"'")&");" -> INSERT INTO octadesk.stickets (ticket,Data_entrada,Data_resolucao,Titulo_ticket,Usuario_criador_ticket,Status,Grupo_responsavel,Responsavel_ticket,Tags_ticket,Total_de_interacoes) values('193177','2025-04-30 15:18:38',NULL,'Incidente - WOZ transcrição não está funcionando como deveria - o184072-481','Juan C.','Pendente','N2','Juan C.','193123, ticket-corrigido','4');
B40: 193178 | C40: =IFERROR(VLOOKUP(Relatorio_[[#This Row],[ticket]],Base!A:A,1,0),"-") -> 193178 | D40: 45777.646 | E40: 45778.728 | F40: =IF(Relatorio_[[#This Row],[Data_resolução]]=0,"",Relatorio_[[#This Row],[Data_resolução]]) -> 45778.728 | G40: Sua conta do WhatsApp Business está violando a política | H40: Facebook | I40: Resolvido | J40: Suporte | K40: Suporte | L40: - | M40: 2 | O40: ="INSERT INTO octadesk.stickets ("&$B$1&","&$D$1&","&$F$1&","&$G$1&","&$H$1&","&$I$1&","&$J$1&","&$K$1&","&$L$1&","&$M$1&") values("&IF(B40="","NULL","'"&B40&"'")&",'"&TEXT(D40,"aaaa-mm-dd hh:mm:ss")&"',"&IF(E40="","NULL","'"&TEXT(E40,"aaaa-mm-dd hh:mm:ss")&"'")&","&IF(G40="","NULL","'"&G40&"'")&","&IF(H40="","NULL","'"&H40&"'")&","&IF(I40="","NULL","'"&I40&"'")&","&IF(J40="","NULL","'"&J40&"'")&","&IF(K40="","NULL","'"&K40&"'")&","&IF(L40="","NULL","'"&L40&"'")&","&IF(M40="","NULL","'"&M40&"'")&");" -> INSERT INTO octadesk.stickets (ticket,Data_entrada,Data_resolucao,Titulo_ticket,Usuario_criador_ticket,Status,Grupo_responsavel,Responsavel_ticket,Tags_ticket,Total_de_interacoes) values('193178','2025-04-30 15:30:24','2025-05-01 17:28:47','Sua conta do WhatsApp Business está violando a política','Facebook','Resolvido','Suporte','Suporte','-','2');
...
